Workbook

Sheet Test Cases
A1: BỘ TEST CASE GIAO DIỆN (FRONTEND) - DỰ ÁN FANDOMVERSE
A2: Dự án: FandomVerse | Phiên bản: v1.0 (UI-only) | Ngày cập nhật: 23/09/2026 | Người tạo: [Tên QA] | Phạm vi: Chỉ kiểm thử giao diện (Frontend) SPA client-side, không gọi API backend thực tế, không kiểm tra Database
A4: A. TRANG CHỦ (HOME PAGE) (12 test case)
A5: STT | B5: ID/Mã kiểm thử | C5: Tên kiểm thử | D5: Mô tả kiểm thử | E5: Môi trường kiểm thử | F5: Các bước thực hiện | G5: Dữ liệu để kiểm thử | H5: Kết quả mong đợi | I5: Kết quả thực tế | J5: Đánh giá | K5: Mức độ ưu tiên | L5: Người thực hiện | M5: Ngày thực hiện | N5: Ghi chú
A6: 1 | B6: TC_HOME_01 | C6: Hiển thị đầy đủ thành phần giao diện trang chủ khi tải lần đầu | D6: Kiểm tra khi mở trang chủ lần đầu, toàn bộ thành phần UI cốt lõi (logo, tiêu đề, giới thiệu, nav, carousel, chatbot) hiển thị đầy đủ. | E6: Web: Chrome 125+, Firefox 126+, Safari 17+ / Windows 11 & macOS URL: https://fandomverse.example.com/#home | F6: 1. Mở trình duyệt, truy cập URL trang chủ 2. Quan sát toàn bộ khung màn hình từ trên xuống dưới 3. Đối chiếu với danh sách thành phần yêu cầu ở SRS mục 1.6.1 | G6: Không cần dữ liệu nhập - chỉ quan sát giao diện tải lần đầu | H6: - Logo portal, tiêu đề động, đoạn giới thiệu hiển thị đầy đủ, không lỗi ảnh vỡ. - Thanh điều hướng 7 danh mục hiển thị đúng. - Carousel nội dung nổi bật và icon chatbot hiển thị. - Không có phần tử nào bị che khuất hoặc lỗi layout. | J6: Untested | K6: Critical | N6: Happy path - luôn chạy đầu tiên trong nhóm Trang chủ.
A7: 2 | B7: TC_HOME_02 | C7: Hiệu ứng animation tiêu đề chạy mượt, không giật/lag | D7: Kiểm tra tiêu đề động (animated title heading) trên trang chủ chạy hiệu ứng đúng như thiết kế và không gây giật hình. | E7: Web: Chrome 125+, Firefox 126+, Safari 17+ / Windows 11 & macOS URL: https://fandomverse.example.com/#home | F7: 1. Truy cập trang chủ, tải lại trang (F5) 3 lần liên tiếp 2. Quan sát hiệu ứng chữ/logo tại vùng tiêu đề mỗi lần tải 3. Dùng DevTools > Performance ghi lại 5s đầu để kiểm tra FPS | G7: Không có dữ liệu nhập cụ thể | H7: Hiệu ứng animation chạy mượt (không giật, không nháy), lặp lại nhất quán qua các lần tải; FPS không tụt xuống dưới ngưỡng gây khó chịu (ước lượng quan sát). | J7: Untested | K7: Minor
A8: 3 | B8: TC_HOME_03 | C8: Thanh điều hướng hiển thị đủ 7 danh mục đúng thứ tự | D8: Kiểm tra navbar/grid điều hướng trang chủ hiển thị đầy đủ và đúng thứ tự 7 danh mục theo SRS. | E8: Web: Chrome 125+, Firefox 126+, Safari 17+ / Windows 11 & macOS URL: https://fandomverse.example.com/#home | F8: 1. Truy cập trang chủ 2. Quan sát danh sách danh mục trên thanh điều hướng hoặc lưới danh mục 3. Đối chiếu tên và thứ tự với SRS mục 1.2 | G8: Danh sách kỳ vọng: Anime, Gaming, Movies, TV Shows, K-Pop, Comics, Manga | H8: Hiển thị đầy đủ và đúng thứ tự 7 danh mục, không thiếu/thừa/sai chính tả tên danh mục. | J8: Untested | K8: Major
A9: 4 | B9: TC_HOME_04 | C9: Click từng danh mục điều hướng đúng tới Category Hub tương ứng | D9: Kiểm tra khi click vào mỗi mục trên navbar, hệ thống điều hướng đúng tới trang Category Hub tương ứng (data-driven cho cả 7 danh mục). | E9: Web: Chrome 125+, Firefox 126+, Safari 17+ / Windows 11 & macOS URL: https://fandomverse.example.com/#home | F9: 1. Truy cập trang chủ 2. Lần lượt click từng danh mục trong navbar (7 lần) 3. Sau mỗi lần click, quan sát URL hash và tiêu đề trang hiển thị | G9: 7 danh mục: Anime, Gaming, Movies, TV Shows, K-Pop, Comics, Manga | H9: Mỗi lần click điều hướng đúng tới Category Hub tương ứng (URL đổi đúng hash, tiêu đề trang khớp tên danh mục), không nhảy nhầm trang. | J9: Untested | K9: Critical | N9: Data-driven testing cho 7 danh mục.
A10: 5 | B10: TC_HOME_05 | C10: Carousel nội dung nổi bật tự động chuyển slide theo thời gian | D10: Kiểm tra khu vực Featured Content trên trang chủ tự động chuyển slide sau một khoảng thời gian cố định. | E10: Web: Chrome 125+, Firefox 126+, Safari 17+ / Windows 11 & macOS URL: https://fandomverse.example.com/#home | F10: 1. Truy cập trang chủ 2. Không thao tác gì, quan sát và bấm giờ khoảng thời gian giữa 2 lần chuyển slide liên tiếp (đo 3 lần) 3. Ghi nhận nội dung hiển thị ở mỗi slide | G10: Không có dữ liệu nhập cụ thể | H10: Carousel tự động chuyển slide theo chu kỳ thời gian nhất quán (sai số nhỏ), nội dung mỗi slide hiển thị đúng ảnh/tiêu đề tương ứng dữ liệu JSON. | J10: Untested | K10: Minor
A11: 6 | B11: TC_HOME_06 | C11: Điều hướng thủ công carousel bằng nút Next/Prev và chấm chỉ số | D11: Kiểm tra người dùng có thể chủ động chuyển slide bằng nút mũi tên hoặc click vào chấm chỉ số (dots). | E11: Web: Chrome 125+, Firefox 126+, Safari 17+ / Windows 11 & macOS URL: https://fandomverse.example.com/#home | F11: 1. Truy cập trang chủ 2. Click nút Next 2 lần, quan sát slide chuyển đúng thứ tự 3. Click nút Prev 1 lần, quan sát quay lại đúng slide trước 4. Click trực tiếp vào 1 chấm chỉ số bất kỳ | G11: Không có dữ liệu nhập cụ thể | H11: Slide chuyển đúng theo thao tác người dùng ở cả 3 cách; chấm chỉ số đang active cập nhật đúng vị trí slide hiện tại. | J11: Untested | K11: Minor
A12: 7 | B12: TC_HOME_07 | C12: Click item carousel điều hướng đúng tới trang chi tiết | D12: Kiểm tra khi click vào 1 item trong carousel Featured Content, hệ thống điều hướng đúng tới trang chi tiết nội dung tương ứng. | E12: Web: Chrome 125+, Firefox 126+, Safari 17+ / Windows 11 & macOS URL: https://fandomverse.example.com/#home | F12: 1. Truy cập trang chủ 2. Ghi nhận tiêu đề item đang hiển thị trên carousel 3. Click vào item đó 4. Quan sát trang được điều hướng tới | G12: Item carousel bất kỳ đang hiển thị (bài viết/trailer/sự kiện) | H12: Điều hướng đúng tới trang chi tiết của item đã click, nội dung trang chi tiết khớp với item đã chọn trên carousel. | J12: Untested | K12: Major
A13: 8 | B13: TC_HOME_08 | C13: Icon Chatbot Launcher luôn hiển thị cố định khi cuộn trang | D13: Kiểm tra icon chatbot nổi (floating) giữ nguyên vị trí cố định trên màn hình khi người dùng cuộn trang chủ. | E13: Web: Chrome 125+, Firefox 126+, Safari 17+ / Windows 11 & macOS URL: https://fandomverse.example.com/#home | F13: 1. Truy cập trang chủ 2. Cuộn trang xuống hết nội dung (scroll to bottom) 3. Quan sát vị trí icon chatbot trong suốt quá trình cuộn | G13: Không có dữ liệu nhập cụ thể | H13: Icon chatbot luôn hiển thị cố định (fixed position) ở cùng 1 vị trí góc màn hình trong suốt quá trình cuộn trang, không bị che bởi nội dung khác. | J13: Untested | K13: Minor
A14: 9 | B14: TC_HOME_09 | C14: Trang chủ hiển thị đúng và responsive trên thiết bị di động | D14: Kiểm tra layout trang chủ chuyển đổi đúng sang giao diện mobile (menu hamburger, carousel dạng dọc/vuốt) khi truy cập từ thiết bị di động. | E14: Web: Chrome 125+, Firefox 126+, Safari 17+ / Windows 11 & macOS URL: https://fandomverse.example.com/#home | F14: 1. Mở trình duyệt mobile hoặc thu nhỏ viewport về 375px 2. Truy cập trang chủ 3. Kiểm tra menu điều hướng chuyển thành dạng hamburger/thu gọn 4. Vuốt carousel Featured Content | G14: Không có dữ liệu nhập cụ thể | H14: Layout không bị vỡ, không tràn ngang; menu điều hướng thu gọn dạng hamburger hoạt động đúng; carousel vuốt được bằng thao tác chạm (swipe). | J14: Untested | K14: Major
A15: 10 | B15: TC_HOME_10 | C15: Trang chủ hiển thị trạng thái loading khi đang tải dữ liệu JSON | D15: Kiểm tra giao diện hiển thị skeleton/spinner hợp lý trong lúc các file JSON dữ liệu Featured Content đang được fetch. | E15: Web: Chrome 125+, Firefox 126+, Safari 17+ / Windows 11 & macOS URL: https://fandomverse.example.com/#home | F15: 1. Mở DevTools > Network, bật Throttling "Slow 3G" 2. Truy cập/tải lại trang chủ 3. Quan sát trạng thái giao diện trong lúc dữ liệu đang tải | G15: Điều kiện mạng: Slow 3G (throttled) | H15: Hiển thị skeleton loading hoặc spinner tại khu vực carousel/nội dung đang chờ dữ liệu, không hiển thị khung trắng/lỗi trong lúc chờ. | J15: Untested | K15: Minor | N15: Kiểm thử trải nghiệm khi mạng chậm.
A16: 11 | B16: TC_HOME_11 | C16: Xử lý khi file JSON Featured Content lỗi hoặc không tải được | D16: Kiểm tra giao diện xử lý hợp lý (không crash trắng trang) khi file JSON dữ liệu nội dung nổi bật bị lỗi hoặc không truy cập được. | E16: Web: Chrome 125+, Firefox 126+, Safari 17+ / Windows 11 & macOS URL: https://fandomverse.example.com/#home | F16: 1. Dùng DevTools > Network, chặn (block) request tới file contents.json hoặc events.json 2. Tải lại trang chủ 3. Quan sát khu vực Featured Content | G16: Request tới file JSON dữ liệu Featured Content bị chặn (giả lập lỗi tải) | H16: Khu vực Featured Content hiển thị thông báo lỗi/thông báo trống hợp lý (VD: "Không thể tải nội dung, vui lòng thử lại"), các phần khác của trang vẫn hoạt động bình thường, không phát sinh lỗi console nghiêm trọng. | J16: Untested | K16: Major
A17: 12 | B17: TC_HOME_12 | C17: Khả năng điều hướng bàn phím cho menu và carousel trang chủ | D17: Kiểm tra toàn bộ navbar và carousel trên trang chủ có thể thao tác hoàn toàn bằng bàn phím (Accessibility). | E17: Web: Chrome 125+, Firefox 126+, Safari 17+ / Windows 11 & macOS URL: https://fandomverse.example.com/#home | F17: 1. Truy cập trang chủ, click vào vùng nội dung để focus 2. Dùng phím Tab để di chuyển qua từng mục navbar và nút carousel 3. Dùng phím Enter để kích hoạt 1 mục navbar đang focus | G17: Không có dữ liệu nhập cụ thể - thao tác hoàn toàn bằng bàn phím | H17: Thứ tự Tab logic từ trên xuống dưới, trái sang phải; mỗi phần tử có viền focus rõ ràng; Enter kích hoạt điều hướng đúng như khi click chuột. | J17: Untested | K17: Minor | N17: Kiểm thử khả năng tiếp cận (Accessibility/A11y).
A19: B. DANH MỤC FANDOM (CATEGORY HUB) (20 test case)
A20: STT | B20: ID/Mã kiểm thử | C20: Tên kiểm thử | D20: Mô tả kiểm thử | E20: Môi trường kiểm thử | F20: Các bước thực hiện | G20: Dữ liệu để kiểm thử | H20: Kết quả mong đợi | I20: Kết quả thực tế | J20: Đánh giá | K20: Mức độ ưu tiên | L20: Người thực hiện | M20: Ngày thực hiện | N20: Ghi chú
A21: 1 | B21: TC_CAT_01 | C21: Truy cập Category Hub Anime hiển thị đúng danh sách nội dung (Happy path) | D21: Kiểm tra khi truy cập Category Hub "Anime", giao diện render đúng danh sách card nội dung từ contents.json. | E21: Web: Chrome 125+, Firefox 126+, Safari 17+ / Windows 11 & macOS URL: https://fandomverse.example.com/#anime | F21: 1. Truy cập trang chủ 2. Click danh mục "Anime" 3. Quan sát danh sách card nội dung hiển thị 4. Đối chiếu số lượng/nội dung với dữ liệu contents.json mẫu | G21: Danh mục: Anime | H21: Danh sách card nội dung Anime hiển thị đầy đủ, đúng dữ liệu nguồn, không có card trống hoặc dữ liệu sai danh mục. | J21: Untested | K21: Critical | N21: Happy path - chạy đầu tiên nhóm Category Hub.
A22: 2 | B22: TC_CAT_02 | C22: Card nội dung hiển thị đầy đủ các trường bắt buộc | D22: Kiểm tra mỗi card nội dung trong Category Hub hiển thị đủ Title, Thumbnail, Mô tả ngắn, Loại nội dung, Sub-tag. | E22: Web: Chrome 125+, Firefox 126+, Safari 17+ / Windows 11 & macOS URL: https://fandomverse.example.com/#anime | F22: 1. Truy cập 1 Category Hub bất kỳ (VD: Gaming) 2. Chọn ngẫu nhiên 3 card bất kỳ 3. Kiểm tra từng trường hiển thị trên mỗi card | G22: Danh mục: Gaming, kiểm tra 3 card ngẫu nhiên | H22: Mỗi card hiển thị đầy đủ 5 trường: Title, Thumbnail, Mô tả ngắn, Loại nội dung (badge/icon), Sub-tag; không có trường nào bị thiếu hoặc hiển thị "undefined". | J22: Untested | K22: Major
A23: 3 | B23: TC_CAT_03 | C23: Data-driven: Truy cập đủ cả 7 Category Hub hiển thị đúng nội dung riêng biệt | D23: Kiểm tra lần lượt cả 7 Category Hub chỉ hiển thị đúng nội dung thuộc danh mục tương ứng, không lẫn dữ liệu danh mục khác. | E23: Web: Chrome 125+, Firefox 126+, Safari 17+ / Windows 11 & macOS URL: https://fandomverse.example.com/#anime | F23: 1. Lần lượt truy cập từng Category Hub: Anime, Gaming, Movies, TV Shows, K-Pop, Comics, Manga 2. Với mỗi hub, kiểm tra toàn bộ card hiển thị đều thuộc đúng danh mục đang chọn | G23: 7 danh mục: Anime, Gaming, Movies, TV Shows, K-Pop, Comics, Manga | H23: Mỗi Category Hub chỉ hiển thị nội dung đúng danh mục của nó, không xuất hiện card thuộc danh mục khác ở bất kỳ hub nào. | J23: Untested | K23: Critical | N23: Data-driven testing cho toàn bộ 7 danh mục.
A24: 4 | B24: TC_CAT_04 | C24: Bộ lọc theo loại nội dung hoạt động đúng | D24: Kiểm tra bộ lọc Content Type (Article/Gallery/Video/Audio/Character/Event/Merchandise/Release) lọc đúng danh sách card hiển thị. | E24: Web: Chrome 125+, Firefox 126+, Safari 17+ / Windows 11 & macOS URL: https://fandomverse.example.com/#anime | F24: 1. Truy cập Category Hub "Movies" 2. Chọn lần lượt từng loại nội dung trong bộ lọc 3. Sau mỗi lần chọn, kiểm tra danh sách card chỉ còn đúng loại đã chọn | G24: Danh mục: Movies; lần lượt chọn từng loại: Article, Gallery, Video, Audio, Character, Event, Merchandise, Release | H24: Với mỗi lựa chọn, danh sách chỉ hiển thị đúng card thuộc loại nội dung đã chọn, không lẫn loại khác. | J24: Untested | K24: Major | N24: Data-driven cho 8 loại nội dung.
A25: 5 | B25: TC_CAT_05 | C25: Chọn nhiều bộ lọc loại nội dung cùng lúc (multi-select) | D25: Kiểm tra khi chọn đồng thời nhiều loại nội dung trong bộ lọc, danh sách hiển thị đúng hợp (union) các loại đã chọn. | E25: Web: Chrome 125+, Firefox 126+, Safari 17+ / Windows 11 & macOS URL: https://fandomverse.example.com/#anime | F25: 1. Truy cập Category Hub "Comics" 2. Tick chọn đồng thời 2 loại: "Gallery" và "Video" 3. Quan sát danh sách card kết quả | G25: Danh mục: Comics; chọn đồng thời: Gallery + Video | H25: Danh sách hiển thị đúng tất cả card thuộc loại Gallery HOẶC Video, không hiển thị loại khác, không bị trùng lặp card. | J25: Untested | K25: Minor
A26: 6 | B26: TC_CAT_06 | C26: Bộ lọc theo Sub-tag danh mục hoạt động đúng | D26: Kiểm tra bộ lọc theo Sub-tag (VD: Shounen, Isekai đối với Anime) lọc đúng danh sách card tương ứng. | E26: Web: Chrome 125+, Firefox 126+, Safari 17+ / Windows 11 & macOS URL: https://fandomverse.example.com/#anime | F26: 1. Truy cập Category Hub "Anime" 2. Chọn Sub-tag "Isekai" trong bộ lọc 3. Quan sát danh sách card kết quả | G26: Danh mục: Anime; Sub-tag: Isekai | H26: Danh sách chỉ hiển thị đúng các card có gắn Sub-tag "Isekai", không lẫn nội dung không thuộc sub-tag này. | J26: Untested | K26: Minor
A27: 7 | B27: TC_CAT_07 | C27: Sắp xếp Alphabetical (A-Z và Z-A) hoạt động đúng | D27: Kiểm tra tùy chọn sắp xếp theo bảng chữ cái sắp đúng thứ tự tăng dần và giảm dần theo Title. | E27: Web: Chrome 125+, Firefox 126+, Safari 17+ / Windows 11 & macOS URL: https://fandomverse.example.com/#anime | F27: 1. Truy cập Category Hub "TV Shows" 2. Chọn Sort "A-Z", ghi nhận thứ tự Title 5 card đầu 3. Chọn Sort "Z-A", ghi nhận lại thứ tự | G27: Danh mục: TV Shows; Sort: A-Z, Z-A | H27: Danh sách sắp xếp đúng thứ tự bảng chữ cái tăng dần khi chọn A-Z, và giảm dần khi chọn Z-A. | J27: Untested | K27: Minor
A28: 8 | B28: TC_CAT_08 | C28: Sắp xếp Newest hiển thị nội dung mới nhất lên đầu | D28: Kiểm tra tùy chọn sắp xếp Newest hiển thị đúng nội dung có ngày đăng/ngày phát hành mới nhất lên đầu danh sách. | E28: Web: Chrome 125+, Firefox 126+, Safari 17+ / Windows 11 & macOS URL: https://fandomverse.example.com/#anime | F28: 1. Truy cập Category Hub "K-Pop" 2. Chọn Sort "Newest" 3. Đối chiếu ngày đăng của 3 card đầu tiên | G28: Danh mục: K-Pop; Sort: Newest | H28: 3 card đầu tiên có ngày đăng/phát hành mới nhất, thứ tự giảm dần theo thời gian đến cuối danh sách. | J28: Untested | K28: Minor
A29: 9 | B29: TC_CAT_09 | C29: Sắp xếp Popularity/Featured hoạt động đúng | D29: Kiểm tra tùy chọn sắp xếp theo mức độ phổ biến/nổi bật hiển thị đúng thứ tự theo cờ featured/popularity trong dữ liệu. | E29: Web: Chrome 125+, Firefox 126+, Safari 17+ / Windows 11 & macOS URL: https://fandomverse.example.com/#anime | F29: 1. Truy cập Category Hub "Manga" 2. Chọn Sort "Popularity/Featured" 3. Đối chiếu thứ tự hiển thị với trường popularity/featured trong contents.json | G29: Danh mục: Manga; Sort: Popularity/Featured | H29: Danh sách sắp xếp đúng theo mức độ phổ biến/nổi bật giảm dần, khớp với dữ liệu nguồn. | J29: Untested | K29: Minor
A30: 10 | B30: TC_CAT_10 | C30: Kết hợp đồng thời Filter và Sort | D30: Kiểm tra khi áp dụng đồng thời bộ lọc loại nội dung và tùy chọn sắp xếp, kết quả hiển thị đúng cả 2 điều kiện. | E30: Web: Chrome 125+, Firefox 126+, Safari 17+ / Windows 11 & macOS URL: https://fandomverse.example.com/#anime | F30: 1. Truy cập Category Hub "Gaming" 2. Chọn Filter "Video" 3. Chọn thêm Sort "Newest" 4. Quan sát danh sách kết quả | G30: Danh mục: Gaming; Filter: Video; Sort: Newest | H30: Danh sách chỉ hiển thị card loại Video, được sắp xếp đúng theo Newest (mới nhất lên đầu). | J30: Untested | K30: Major
A31: 11 | B31: TC_CAT_11 | C31: Nút Clear Filters reset về danh sách đầy đủ | D31: Kiểm tra nút xóa bộ lọc (Clear Filters) đưa danh sách trở về trạng thái ban đầu, không còn áp dụng filter/sort nào. | E31: Web: Chrome 125+, Firefox 126+, Safari 17+ / Windows 11 & macOS URL: https://fandomverse.example.com/#anime | F31: 1. Truy cập Category Hub bất kỳ, áp dụng 1 filter loại nội dung và 1 tùy chọn sort 2. Nhấn nút "Xóa bộ lọc" 3. Quan sát danh sách và trạng thái các control filter/sort | G31: Danh mục bất kỳ (VD: Anime); Filter: Character; Sort: Newest | H31: Danh sách trở về đầy đủ toàn bộ nội dung của danh mục, các control filter/sort trở về trạng thái mặc định (chưa chọn). | J31: Untested | K31: Minor
A32: 12 | B32: TC_CAT_12 | C32: Trạng thái Empty khi bộ lọc không khớp nội dung nào | D32: Kiểm tra giao diện hiển thị thông báo hợp lý khi kết hợp bộ lọc dẫn tới không có kết quả nào. | E32: Web: Chrome 125+, Firefox 126+, Safari 17+ / Windows 11 & macOS URL: https://fandomverse.example.com/#anime | F32: 1. Truy cập Category Hub "K-Pop" 2. Chọn kết hợp Filter "Merchandise" + Sub-tag không tồn tại dữ liệu tương ứng (nếu có) 3. Quan sát khu vực danh sách kết quả | G32: Danh mục: K-Pop; Filter kết hợp không có dữ liệu khớp | H32: Hiển thị thông báo/illustration "Không tìm thấy nội dung phù hợp" rõ ràng, không hiển thị khung trắng hoặc lỗi giao diện. | J32: Untested | K32: Minor
A33: 13 | B33: TC_CAT_13 | C33: Click card nội dung điều hướng đúng tới trang chi tiết | D33: Kiểm tra khi click vào 1 card bất kỳ trong Category Hub, hệ thống điều hướng đúng tới trang chi tiết tương ứng loại nội dung của card đó. | E33: Web: Chrome 125+, Firefox 126+, Safari 17+ / Windows 11 & macOS URL: https://fandomverse.example.com/#anime | F33: 1. Truy cập Category Hub "Comics" 2. Chọn 1 card loại "Article" và click vào 3. Quan sát trang được điều hướng tới 4. Quay lại, lặp lại với 1 card loại "Character" | G33: Danh mục: Comics; loại card: Article, Character | H33: Mỗi loại card điều hướng đúng tới đúng dạng trang chi tiết tương ứng (trang bài viết cho Article, trang hồ sơ cho Character), nội dung khớp với card đã chọn. | J33: Untested | K33: Major
A34: 14 | B34: TC_CAT_14 | C34: Tải thêm/phân trang khi danh mục có nhiều nội dung | D34: Kiểm tra cơ chế Load more/Infinite scroll hoạt động đúng khi Category Hub có số lượng nội dung lớn hơn 1 trang hiển thị. | E34: Web: Chrome 125+, Firefox 126+, Safari 17+ / Windows 11 & macOS URL: https://fandomverse.example.com/#anime | F34: 1. Truy cập Category Hub có nhiều nội dung nhất (VD: Anime) 2. Cuộn xuống cuối danh sách hiện tại hoặc nhấn nút "Xem thêm" (nếu có) 3. Quan sát nội dung mới được tải thêm | G34: Danh mục: Anime (giả định có nhiều bản ghi trong contents.json) | H34: Nội dung mới được tải thêm đúng, không trùng lặp với nội dung đã hiển thị trước đó, có trạng thái loading trong lúc tải thêm. | J34: Untested | K34: Minor | N34: Chỉ áp dụng nếu danh mục có đủ lượng dữ liệu vượt 1 trang.
A35: 15 | B35: TC_CAT_15 | C35: Card hiển thị hợp lý khi thiếu trường dữ liệu tùy chọn trong JSON | D35: Kiểm tra giao diện xử lý hợp lý khi 1 bản ghi trong contents.json thiếu trường tùy chọn (VD: thiếu thumbnail). | E35: Web: Chrome 125+, Firefox 126+, Safari 17+ / Windows 11 & macOS URL: https://fandomverse.example.com/#anime | F35: 1. Chuẩn bị 1 bản ghi test thiếu trường "thumbnail" trong contents.json (môi trường Staging) 2. Truy cập Category Hub chứa bản ghi đó 3. Quan sát card tương ứng | G35: Bản ghi thiếu trường thumbnail | H35: Card hiển thị ảnh placeholder mặc định thay cho thumbnail bị thiếu, không vỡ layout, không hiển thị ô trống/lỗi ảnh (broken icon). | J35: Untested | K35: Minor
A36: 16 | B36: TC_CAT_16 | C36: Breadcrumb hiển thị đúng khi ở trong Category Hub | D36: Kiểm tra breadcrumb hiển thị đúng đường dẫn khi người dùng đang ở 1 Category Hub bất kỳ. | E36: Web: Chrome 125+, Firefox 126+, Safari 17+ / Windows 11 & macOS URL: https://fandomverse.example.com/#anime | F36: 1. Truy cập Category Hub "Movies" 2. Quan sát breadcrumb ở đầu trang | G36: Danh mục: Movies | H36: Breadcrumb hiển thị đúng dạng "Trang chủ > Movies", mỗi mắt xích là link hoạt động được. | J36: Untested | K36: Minor
A37: 17 | B37: TC_CAT_17 | C37: Category Hub responsive đúng trên tablet và mobile | D37: Kiểm tra lưới card trong Category Hub co giãn hợp lý theo kích thước màn hình tablet và mobile. | E37: Mobile: Android 14 (Samsung/Pixel) & iOS 17 - Safari/Chrome Mobile URL: https://fandomverse.example.com/#anime | F37: 1. Thu nhỏ viewport về kích thước tablet (768px), truy cập Category Hub "Anime" 2. Quan sát số cột lưới card 3. Thu nhỏ tiếp về kích thước mobile (375px), quan sát lại | G37: Danh mục: Anime; viewport: 768px và 375px | H37: Lưới card tự động giảm số cột hợp lý theo từng kích thước màn hình, không tràn ngang, card không bị méo/chồng lấp. | J37: Untested | K37: Major
A38: 18 | B38: TC_CAT_18 | C38: Hiệu năng tải Category Hub với bộ dữ liệu JSON lớn | D38: Kiểm tra giao diện không bị treo/giật khi Category Hub tải một lượng lớn bản ghi từ JSON. | E38: Web: Chrome 125+, Firefox 126+, Safari 17+ / Windows 11 & macOS URL: https://fandomverse.example.com/#anime | F38: 1. Chuẩn bị file contents.json test với số lượng bản ghi lớn (VD: 500 bản ghi) cho 1 danh mục (môi trường Staging) 2. Truy cập Category Hub tương ứng 3. Quan sát thời gian tải và độ mượt khi cuộn trang | G38: contents.json với ~500 bản ghi cho 1 danh mục test | H38: Trang tải trong thời gian hợp lý, có trạng thái loading rõ ràng; cuộn trang mượt, không bị đơ/treo giao diện. | J38: Untested | K38: Minor | N38: Kiểm thử hiệu năng với dữ liệu lớn.
A39: 19 | B39: TC_CAT_19 | C39: Trạng thái Filter/Sort được giữ khi quay lại từ trang chi tiết | D39: Kiểm tra khi người dùng áp dụng filter/sort, mở 1 card chi tiết rồi bấm Back, trạng thái filter/sort trên Category Hub được giữ nguyên. | E39: Web: Chrome 125+, Firefox 126+, Safari 17+ / Windows 11 & macOS URL: https://fandomverse.example.com/#anime | F39: 1. Truy cập Category Hub "Gaming", áp dụng Filter "Video" + Sort "Newest" 2. Click vào 1 card bất kỳ để mở trang chi tiết 3. Nhấn nút Back của trình duyệt | G39: Danh mục: Gaming; Filter: Video; Sort: Newest | H39: Sau khi Back, Category Hub hiển thị lại đúng trạng thái Filter "Video" và Sort "Newest" đã áp dụng trước đó, không bị reset về mặc định. | J39: Untested | K39: Minor
A40: 20 | B40: TC_CAT_20 | C40: Khả năng tiếp cận bàn phím cho bộ lọc Category Hub | D40: Kiểm tra người dùng có thể điều hướng và chọn các control filter/sort hoàn toàn bằng bàn phím. | E40: Web: Chrome 125+, Firefox 126+, Safari 17+ / Windows 11 & macOS URL: https://fandomverse.example.com/#anime | F40: 1. Truy cập Category Hub "Manga" 2. Dùng phím Tab di chuyển tới control Filter, dùng Space/Enter để chọn 1 loại nội dung 3. Tiếp tục Tab tới control Sort, chọn 1 tùy chọn bằng bàn phím | G40: Danh mục: Manga | H40: Toàn bộ control filter/sort có thể thao tác đầy đủ bằng bàn phím, có viền focus rõ ràng, kết quả lọc/sắp xếp áp dụng đúng như khi dùng chuột. | J40: Untested | K40: Minor | N40: Kiểm thử khả năng tiếp cận (Accessibility/A11y).
A42: C. TÌM KIẾM TOÀN CỤC (GLOBAL SEARCH) (15 test case)
A43: STT | B43: ID/Mã kiểm thử | C43: Tên kiểm thử | D43: Mô tả kiểm thử | E43: Môi trường kiểm thử | F43: Các bước thực hiện | G43: Dữ liệu để kiểm thử | H43: Kết quả mong đợi | I43: Kết quả thực tế | J43: Đánh giá | K43: Mức độ ưu tiên | L43: Người thực hiện | M43: Ngày thực hiện | N43: Ghi chú
...

Sheet Tổng hợp
A1: TỔNG HỢP KẾT QUẢ KIỂM THỬ GIAO DIỆN - FANDOMVERSE
A3: Chỉ số | B3: Số lượng
A4: Tổng số Test Case | B4: =COUNTA('Test Cases'!B4:B245)-14 -> 200
A5: Số lượng Pass | B5: =COUNTIF('Test Cases'!J4:J245,"Pass") -> 0
A6: Số lượng Fail | B6: =COUNTIF('Test Cases'!J4:J245,"Fail") -> 0
A7: Số lượng Blocked | B7: =COUNTIF('Test Cases'!J4:J245,"Blocked") -> 0
A8: Số lượng Untested | B8: =COUNTIF('Test Cases'!J4:J245,"Untested") -> 200
A9: Ngày cập nhật | B9: 23/09/2026
A11: Phân bổ theo module
A12: Module | B12: Số lượng TC
A13: A. TRANG CHỦ (HOME PAGE) | B13: =COUNTIF('Test Cases'!$B$4:$B$245,"TC_HOME_*") -> 12
A14: B. DANH MỤC FANDOM (CATEGORY HUB) | B14: =COUNTIF('Test Cases'!$B$4:$B$245,"TC_CAT_*") -> 20
A15: C. TÌM KIẾM TOÀN CỤC (GLOBAL SEARCH) | B15: =COUNTIF('Test Cases'!$B$4:$B$245,"TC_SEARCH_*") -> 15
A16: D. THƯ VIỆN ẢNH (IMAGE GALLERY / LIGHTBOX) | B16: =COUNTIF('Test Cases'!$B$4:$B$245,"TC_GAL_*") -> 10
A17: E. VIDEO & AUDIO | B17: =COUNTIF('Test Cases'!$B$4:$B$245,"TC_MEDIA_*") -> 12
A18: F. BÀI VIẾT NỔI BẬT (FEATURED ARTICLES) | B18: =COUNTIF('Test Cases'!$B$4:$B$245,"TC_ART_*") -> 10
A19: G. HỒ SƠ NHÂN VẬT (CHARACTER PROFILES) | B19: =COUNTIF('Test Cases'!$B$4:$B$245,"TC_CHAR_*") -> 14
A20: H. SỰ KIỆN (EVENT HIGHLIGHTS) | B20: =COUNTIF('Test Cases'!$B$4:$B$245,"TC_EVT_*") -> 10
A21: I. TRAILER | B21: =COUNTIF('Test Cases'!$B$4:$B$245,"TC_TRL_*") -> 12
A22: J. MERCHANDISE & GIỎ HÀNG | B22: =COUNTIF('Test Cases'!$B$4:$B$245,"TC_MERCH_*") -> 22
A23: K. CHATBOT AI | B23: =COUNTIF('Test Cases'!$B$4:$B$245,"TC_BOT_*") -> 16
A24: L. BOOKMARK & GHI CHÚ | B24: =COUNTIF('Test Cases'!$B$4:$B$245,"TC_BM_*") -> 14
A25: M. TÍNH NĂNG BỔ SUNG (VISITOR COUNTER, CLOCK, BREADCRUMB, LOGIN GIẢ LẬP, TRANG TĨNH) | B25: =COUNTIF('Test Cases'!$B$4:$B$245,"TC_MISC_*") -> 16
A26: N. TƯƠNG THÍCH, HIỆU NĂNG & KHẢ NĂNG TIẾP CẬN | B26: =COUNTIF('Test Cases'!$B$4:$B$245,"TC_QA_*") -> 17
A28: Phân bổ theo Mức độ ưu tiên
A29: Mức độ | B29: Số lượng TC
A30: Critical | B30: =COUNTIF('Test Cases'!K4:K245,"Critical") -> 17
A31: Major | B31: =COUNTIF('Test Cases'!K4:K245,"Major") -> 65
A32: Minor | B32: =COUNTIF('Test Cases'!K4:K245,"Minor") -> 118

Sheet Hướng dẫn
A1: HƯỚNG DẪN SỬ DỤNG FILE TEST CASE GIAO DIỆN (UI) - DỰ ÁN FANDOMVERSE
A3: 0. Phạm vi của bộ test case này:
A4: - Toàn bộ test case trong file chỉ kiểm thử qua GIAO DIỆN (trình duyệt web / trình duyệt di động), theo đúng kiến trúc FandomVerse là Single Page Application (SPA) client-side, không có backend/database.
A5: - KHÔNG bao gồm: kiểm thử mã nguồn JavaScript chi tiết (unit test), kiểm tra tính đúng đắn của dữ liệu JSON tĩnh ở mức nội dung biên tập, hay các công cụ ngoài trình duyệt/thiết bị thật.
A6: - File JSON tĩnh (contents.json, characters.json, events.json, trailers.json, merchandise.json, chatbot_faq.json) được xem là dữ liệu đầu vào có sẵn; một số test case yêu cầu chuẩn bị bản ghi test riêng trên môi trường Staging (được ghi rõ trong cột Ghi chú).
A8: 1. Cấu trúc file gồm 3 sheet:
A9: - Test Cases: 200 test case chi tiết, chia theo 14 nhóm chức năng bám sát SRS FandomVerse v2.0 (Trang chủ, Category Hub, Tìm kiếm, Gallery, Video/Audio, Bài viết, Nhân vật, Sự kiện, Trailer, Merchandise/Giỏ hàng, Chatbot AI, Bookmark/Ghi chú, Tính năng bổ sung, Tương thích-Hiệu năng-Tiếp cận).
A10: - Tổng hợp: Thống kê nhanh số lượng Pass/Fail/Blocked/Untested và phân bổ theo module, mức độ ưu tiên (tự động tính bằng công thức).
A11: - Hướng dẫn: Trang mô tả cách sử dụng file này.
A13: 2. Giải thích các cột trong sheet Test Cases:
A14: - STT: Số thứ tự của test case trong từng nhóm chức năng.
A15: - ID/Mã kiểm thử: Mã định danh duy nhất theo quy tắc TC_<Module>_<Số> (VD: TC_HOME_01, TC_CAT_01, TC_MERCH_01).
... A39: - Cập nhật lại sheet Tổng hợp (F9 để recalculate) sau mỗi đợt thực thi để có số liệu thống kê mới nhất.
